import { useState, useCallback } from 'react';
import { AxiosError } from 'axios';

interface UseApiState<T> {
  data: T | null;
  loading: boolean;
  error: string | null;
}

interface UseApiReturn<T> extends UseApiState<T> {
  execute: (...args: any[]) => Promise<void>;
  reset: () => void;
}

export function useApi<T>(
  apiFunction: (...args: any[]) => Promise<{ data: T; message?: string }>
): UseApiReturn<T> {
  const [state, setState] = useState<UseApiState<T>>({
    data: null,
    loading: false,
    error: null,
  });

  const execute = useCallback(
    async (...args: any[]) => {
      setState(prev => ({ ...prev, loading: true, error: null }));
      
      try {
        const response = await apiFunction(...args);
        setState({
          data: response.data,
          loading: false,
          error: null,
        });
      } catch (error) {
        const errorMessage = error instanceof AxiosError
          ? error.response?.data?.message || error.message
          : 'An unexpected error occurred';
          
        setState({
          data: null,
          loading: false,
          error: errorMessage,
        });
      }
    },
    [apiFunction]
  );

  const reset = useCallback(() => {
    setState({
      data: null,
      loading: false,
      error: null,
    });
  }, []);

  return {
    ...state,
    execute,
    reset,
  };
}